Workbook

Sheet BALANCE ENERO 2026
C3: TOTAL BARRILES PRODUCIDOS KIMBO ENERO 2026 (FORMAS DE PRODUCCION FISCALIZADAS ANH) | D3: 7402.05
C4: TOTAL BARRILES PRODUCIDOS CALICHE ENERO 2026 (FORMAS DE PRODUCCION FISCALIZADAS ANH) | D4: 8090.62
C5: PRECIO PROMEDIO DE VENTA BRENT ENERO 2026 | D5: 48.64
C6: TRM PROMEDIO ENERO 2026 | D6: =+'COSTOS Y GASTOS ENERO 2026'!D133 -> 3702.999
C8: BALANCE KIMBO ENERO 2026 | G8: BALANCE CALICHE ENERO 2026
C9: CONCEPTO | D9: PROPORCION SOBRE EL INGRESO TOTAL | E9: MONTO (COP) | G9: CONCEPTO | H9: PROPORCION SOBRE EL INGRESO TOTAL | I9: MONTO (COP)
C11: INGRESO TOTAL | E11: =+SUM(D3:D4)*D5*D6 -> 2.7904448e+09 | G11: INGRESO TOTAL | I11: =+SUM(D3:D4)*D5*D6 -> 2.7904448e+09
C12: INGRESOS POR VENTAS KIMBO | D12: =+E12/E11 -> 0.47777756 | E12: =+D3*D5*D6 -> 1.3332119e+09 | G12: INGRESOS POR VENTAS CALICHE | H12: =+I12/$I$11 -> 0.52222244 | I12: =+D4*D5*D6 -> 1.4572329e+09
C13: (-) COSTOS DE PRODUCCION | D13: =+E13/$E$11 -> 0.31283618 | E13: =+SUM('COSTOS Y GASTOS ENERO 2026'!H4:H80)*D12 -> 8.7295208e+08 | G13: (-) COSTOS DE PRODUCCION | H13: =+I13/$I$11 -> 0.34193752 | I13: =++SUM('COSTOS Y GASTOS ENERO 2026'!H4:H80)*H12 -> 9.5415778e+08
C14: (-) GASTOS OPERATIVOS | D14: =+E14/$E$11 -> 0.010145446 | E14: =+SUM('COSTOS Y GASTOS ENERO 2026'!H81:H99)*D12 -> 28310307 | G14: (-) GASTOS OPERATIVOS | H14: =+I14/$I$11 -> 0.011089218 | I14: =+SUM('COSTOS Y GASTOS ENERO 2026'!H81:H99)*H12 -> 30943851
C15: (=) UTILIDAD OPERACIONAL | D15: =+E15/$E$11 -> 0.15479593 | E15: =E12-E13-E14 -> 4.319495e+08 | G15: (=) UTILIDAD OPERACIONAL | H15: =+I15/$I$11 -> 0.1691957 | I15: =I12-I13-I14 -> 4.7213127e+08
C16: (-) REGALIAS ANH (8%) | D16: =+E16/$E$11 -> 0.038222204 | E16: =+E12*8% -> 1.0665695e+08 | G16: (-) REGALIAS ANH (8%) | H16: =+I16/$I$11 -> 0.041777796 | I16: =+I12*8% -> 1.1657863e+08
C17: (=) UTILIDAD BRUTA | D17: =+E17/$E$11 -> 0.11657373 | E17: =+E15-E16 -> 3.2529255e+08 | G17: (=) UTILIDAD BRUTA | H17: =+I17/$I$11 -> 0.12741791 | I17: =+I15-I16 -> 3.5555264e+08
C19: RETORNO A LA INVERSION (KIMBO) | G19: UTILIDAD BRUTA CALICHE
C20: CONCEPTO | D20: VALOR | G20: CONCEPTO | H20: VALOR
C21: UTILIDAD BRUTA | D21: =+E17 -> 3.2529255e+08 | G21: UTILIDAD BRUTA | H21: =I17 -> 3.5555264e+08
C22: PORCENTAJE PARA RECUPERACION | D22: 0.3 | G22: PORCENTAJE POR CONTRATO | H22: 0.3
G23: GANANCIA TOTAL | H23: =+(H21*H22) -> 1.0666579e+08
C24: ABONO PARA RECUPERACION | D24: =+D22*D21 -> 97587765
C27: SALDO INVERSION | D27: 1.1515907e+10
C28: SALDO PENDIENTE POR RECUPERAR | D28: =+D27-D24 -> 1.1418319e+10
C31: Categoria | D31: Total | E31: Porcentaje
C32: Nominas y prestaciones (Nominas, Examenes medicos, dotacion, Seguridad social) | D32: 618949535 | E32: 0.32811776
C33: Arrendamientos Operativos | D33: 414512200 | E33: 0.21974136
C34: Servicio transporte agua de produccion | D34: 265600000 | E34: 0.14079997
C35: Servicios Integrales (Multiples servicios para el desarrollo de la operación en campo) | D35: 122948593 | E35: 0.065177554
C36: Combustible | D36: 112383780 | E36: 0.059576931
C37: Caja menor campo | D37: 70043157 | E37: 0.037131305
C38: Quimicos (quimicos Generales, Quimica para produccion, productos de aseo) | D38: 62580102 | E38: 0.033174987
C39: Provision Recursos Humanos | D39: 50937790 | E39: 0.02700316
C40: Comunidades | D40: 50000000 | E40: 0.026506019
C41: Mantenimiento vias (Transportes de maquinaria, materiales de cantera, irrigacion via) | D41: 29722800 | E41: 0.015756662
C42: Repuestos de Equipo Petrolero | D42: 21573260 | E42: 0.011436425
C43: Honorarios Administrativos | D43: 14147930 | E43: 0.0075001059
... C51: Total general | D51: 1.886364e+09 | E51: 1

Sheet COSTOS Y GASTOS ENERO 2026
C2: COSTOS OPERATIVOS, NOMINAS E IMPUESTOS
C3: Proveedor | D3: concepto | E3: Categoria | F3: Fecha de Facturacion | G3: Numero de factura | H3: Monto | I3: Estado | J3: Fecha de pago | K3: Tipo
C4: Elio aguillon | D4: Saldo liquidacion | E4: Nominas y prestaciones (Nominas, Examenes medicos, dotacion, Seguridad social) | F4: 46027 | G4: Liquidacion | H4: 203216 | I4: PAGADA | J4: 46027 | K4: CP
C5: Maria Bastilla | D5: Saldo liquidacion | E5: Nominas y prestaciones (Nominas, Examenes medicos, dotacion, Seguridad social) | F5: 46027 | G5: Liquidacion | H5: 1246170 | I5: PAGADA | J5: 46027 | K5: CP
C6: Wilson Olaya | D6: Saldo de segunda quincena Diciembre 2025 | E6: Nominas y prestaciones (Nominas, Examenes medicos, dotacion, Seguridad social) | F6: 46028 | G6: Segunda quincena Diciembre 2025 | H6: 500000 | I6: PAGADA | J6: 46028 | K6: CP
C7: AGREGADOS PETREOS DEL ARIPORO | D7: Suministro material de cantera | E7: Mantenimiento vias (Transportes de maquinaria, materiales de cantera, irrigacion via) | F7: 45981 | G7: FE 855 | H7: 2201500 | I7: PAGADA | J7: 46028 | K7: CP
C8: AGREGADOS PETREOS DEL ARIPORO | D8: Suministro material de cantera | E8: Mantenimiento vias (Transportes de maquinaria, materiales de cantera, irrigacion via) | F8: 45981 | G8: FE 856 | H8: 321300 | I8: PAGADA | J8: 46028 | K8: CP
C9: ELOGY TECNOLOGIA ECOLOGICA S.A.S | D9: Tratamiento y disposicion final de aguas residuales | E9: Servicios Integrales (Multiples servicios para el desarrollo de la operación en campo) | F9: 46008 | G9: ELEC 1073 | H9: 1436819 | I9: PAGADA | J9: 46028 | K9: CP
C10: EMMANUEL DOTACIONES | D10: Dotacion Personal | E10: Nominas y prestaciones (Nominas, Examenes medicos, dotacion, Seguridad social) | F10: 46017 | G10: CT1 7389 | H10: 261500 | I10: PAGADA | J10: 46028 | K10: CP
C11: Jose del Carmen Rojas | D11: Insumos campo | E11: Insumos ferreteria | F11: 46010 | G11: N 50038 | H11: 300000 | I11: PAGADA | J11: 46028 | K11: CP
C12: Jose del Carmen Rojas | D12: Insumos campo | E12: Insumos ferreteria | F12: 46013 | G12: N 49993 | H12: 1200000 | I12: PAGADA | J12: 46028 | K12: CP
C13: Martha Duralva Riay | D13: Transporte de grua | E13: Servicios Integrales (Multiples servicios para el desarrollo de la operación en campo) | F13: 46027 | G13: Cuenta de cobro 20250126 | H13: 4800000 | I13: PAGADA | J13: 46028 | K13: CP
C14: MANGUERAS Y RACORES | D14: Repuestos Generales | E14: Repuestos Generales | F14: 46028 | G14: Cotizacion 371 | H14: 1520000 | I14: PAGADA | J14: 46030 | K14: CP
C15: CHARWELD E.U | D15: Renta cargadero OCT 2025 | E15: Arrendamientos Operativos | F15: 45967 | G15: FEV 1261 | H15: 9591400 | I15: PAGADA | J15: 46031 | K15: CP
... C41: AGREGADOS PETREOS DEL ARIPORO | D41: Transporte agua crudo | E41: Servicio transporte agua de produccion | F41: 46001 | G41: FE 866 | H41: 97600000 | I41: PAGADA | J41: 46043 | K41: CP
C42: CAMPAMENTOS CASANARE | E42: Arrendamientos Operativos | F42: 46001 | G42: A 3547 | H42: 32308500 | I42: PAGADA | J42: 46043 | K42: CP
C43: CHARWELD E.U | D43: Renta cargadero NOV 2025 | E43: Arrendamientos Operativos | F43: 45992 | G43: FEV 1264 | H43: 9282000 | I43: PAGADA | J43: 46043 | K43: CP
C44: DON DOTACION | D44: Dotacion Personal | E44: Nominas y prestaciones (Nominas, Examenes medicos, dotacion, Seguridad social) | F44: 46041 | G44: Orden de compra 260118 | H44: 2415700 | I44: PAGADA | J44: 46043 | K44: CP
C45: ELOGY TECNOLOGIA ECOLOGICA S.A.S | D45: Tratamiento y disposicion final de tierras contaminadas, solidos contamidos y solidos ordinarios | E45: Servicios Integrales (Multiples servicios para el desarrollo de la operación en campo) | F45: 46010 | G45: ELEC 1080 | H45: 18652944 | I45: PAGADA | J45: 46043 | K45: CP
C46: EMMANUEL DOTACIONES | D46: Dotacion Personal | E46: Nominas y prestaciones (Nominas, Examenes medicos, dotacion, Seguridad social) | F46: 46042 | G46: RMY 1327 | H46: 980300 | I46: PAGADA | J46: 46043 | K46: CP
C47: EMMANUEL DOTACIONES | D47: Dotacion Personal | E47: Nominas y prestaciones (Nominas, Examenes medicos, dotacion, Seguridad social) | F47: 46036 | G47: CT1 7550 | H47: 240000 | I47: PAGADA | J47: 46043 | K47: CP
C48: ESTANDAR OIL SAS | D48: Alquiler frac tank (01 NOV al 30 NOV 2025) | E48: Arrendamientos Operativos | F48: 46000 | G48: STFE 26 | H48: 27132000 | I48: PAGADA | J48: 46043 | K48: CP
C49: ESTANDAR OIL SAS | D49: Alquiler tanques horizontales (01 NOV al 30 NOV 2025) | E49: Arrendamientos Operativos | F49: 46000 | G49: STFE 27 | H49: 29988000 | I49: PAGADA | J49: 46043 | K49: CP
C50: ESTANDAR OIL SAS | D50: Alquiler tanques verticales (01 NOV al 30 NOV 2025) | E50: Arrendamientos Operativos | F50: 46000 | G50: STFE 28 | H50: 47481000 | I50: PAGADA | J50: 46043 | K50: CP
C51: ESTANDAR OIL SAS | D51: Alquiler gun barrel (01 NOV al 30 NOV 2025) | E51: Arrendamientos Operativos | F51: 46000 | G51: STFE 29 | H51: 18564000 | I51: PAGADA | J51: 46043 | K51: CP
C52: INDETRO INGENIERIA LTDA | D52: .ALQUILER DE 4 TANQUES HORIZONTALES 500 BBL. ( DEL 01 DE OCT AL 31 DE OCT 2025) .ALQUILER 2 PLATAFORMAS (DEL 01 DE OCT AL 31 DE OCT 2025) | E52: Arrendamientos Operativos | F52: 46004 | G52: FV 7952 | H52: 21396200 | I52: PAGADA | J52: 46043 | K52: CP
C53: Jose del Carmen Rojas | D53: Insumos ferreteria | E53: Insumos ferreteria | F53: 46000 | G53: N 49690 | H53: 3113000 | I53: PAGADA | J53: 46043 | K53: CP
C54: Jose del Carmen Rojas | D54: Insumos ferreteria | E54: Insumos ferreteria | F54: 46000 | G54: N 49691 | H54: 372000 | I54: PAGADA | J54: 46043 | K54: CP
... C59: TRANSPORTES ESPECIALES PACIFIC TOURS S.A.S | D59: Servicio de transporte de personal | E59: Servicios Integrales (Multiples servicios para el desarrollo de la operación en campo) | F59: 46002 | G59: PC 159 | H59: 5271500 | I59: PAGADA | J59: 46043 | K59: CP
C60: SEGURIDAD SOCIAL | D60: 46023 | E60: Nominas y prestaciones (Nominas, Examenes medicos, dotacion, Seguridad social) | F60: 46037 | G60: - | H60: 124928300 | I60: PAGADA | J60: 46043 | K60: CP
C61: SERVICIO TECNICO AUTOMOTRIZ O.P.R S.A.S | D61: Repuestos Generales | E61: Repuestos Generales | F61: 46032 | G61: FE 2804 | H61: 1385399 | I61: PAGADA | J61: 46044 | K61: CP
C62: Andres Felipe Sanchez | D62: Elaboracion de inventario forestal | E62: Servicios Integrales (Multiples servicios para el desarrollo de la operación en campo) | F62: 46013 | G62: Cuenta de cobro 01 | H62: 13100000 | I62: PAGADA | J62: 46046 | K62: CP
C63: INOXMAC IMPORTADORA Y COMERCIALIZADORA INDUSTRIAL S.A.S | D63: Repuestos Generales | E63: Repuestos Generales | F63: 46037 | G63: Orden de servicios 260115 | H63: 1368919 | I63: PAGADA | J63: 46046 | K63: CP
C64: MATERIALES ELECTRICOS V M S.A.S | D64: Repuestos Generales | E64: Repuestos Generales | F64: 46035 | G64: Orden de compra 260109 | H64: 3680004 | I64: PAGADA | J64: 46046 | K64: CP
C65: COLCHONES Y SOMIERES SUPER COMODOS S.A.S | D65: Colchones para estacion KIMBO | E65: Repuestos Generales | F65: 46047 | G65: Orden de compra 260123 | H65: 1250000 | I65: PAGADA | J65: 46049 | K65: CP
C66: Diego Alejandro Camacho | D66: Transporte de Unidad de bombeo hidraulico | E66: Servicios Integrales (Multiples servicios para el desarrollo de la operación en campo) | F66: 46038 | G66: Cuenta de Cobro 025 | H66: 5150000 | I66: PAGADA | J66: 46049 | K66: CP
C67: DON DOTACION | D67: Dotacion Personal | E67: Nominas y prestaciones (Nominas, Examenes medicos, dotacion, Seguridad social) | F67: 46048 | G67: Orden de compra 260126 | H67: 4248300 | I67: PAGADA | J67: 46049 | K67: CP
C68: MATERIALES ELECTRICOS V M S.A.S | D68: Repuestos Generales | E68: Repuestos Generales | F68: 46047 | G68: Orden de compra 260124 | H68: 178500 | I68: PAGADA | J68: 46049 | K68: CP
C69: Reinaldo Perez Hurtado | D69: Georeferenciacion y servicios topograficos | E69: Servicios Integrales (Multiples servicios para el desarrollo de la operación en campo) | F69: 46028 | G69: Orden de servicio 260103 | H69: 16500000 | I69: PAGADA | J69: 46049 | K69: CP
C70: Marcelo Rojas Ballesteros | D70: Servicio consultoria juridica | E70: Honorarios Operativos | F70: 46028 | G70: Cuenta de cobro 009 | H70: 4000000 | I70: PAGADA | J70: 46050 | K70: CP
...

Sheet BALANCE FEBRERO 2026
C3: TOTAL BARRILES PRODUCIDOS KIMBO FEBRERO 2026 (FORMAS DE PRODUCCION FISCALIZADAS ANH) | D3: 7427.69
C4: TOTAL BARRILES PRODUCIDOS CALICHE FEBRERO 2026 (FORMAS DE PRODUCCION FISCALIZADAS ANH) | D4: 8060.35
C5: PRECIO PROMEDIO DE VENTA BRENT FEBRERO 2026 | D5: 50.6
C6: TRM PROMEDIO FEBRERO 2026 | D6: =+'COSTOS Y GASTOS FEBRERO 2026'!E139 -> 3675.6414
C8: BALANCE KIMBO FEBRERO 2026 | G8: BALANCE CALICHE FEBRERO 2026
C9: CONCEPTO | D9: PROPORCION SOBRE EL INGRESO TOTAL | E9: MONTO (COP) | G9: CONCEPTO | H9: PROPORCION SOBRE EL INGRESO TOTAL | I9: MONTO (COP)
C11: INGRESO TOTAL | E11: =+SUM(D3:D4)*D5*D6 -> 2.8805812e+09 | G11: INGRESO TOTAL | I11: =+SUM(D3:D4)*D5*D6 -> 2.8805812e+09
C12: INGRESOS POR VENTAS KIMBO | D12: =+E12/E11 -> 0.47957585 | E12: =+D3*D5*D6 -> 1.3814572e+09 | G12: INGRESOS POR VENTAS CALICHE | H12: =+I12/I11 -> 0.52042415 | I12: =+D4*D5*D6 -> 1.499124e+09
C13: (-) COSTOS DE PRODUCCION | D13: =+E13/$E$11 -> 0.29907824 | E13: =+SUM('COSTOS Y GASTOS FEBRERO 2026'!I4:I87)*D12 -> 8.6151915e+08 | G13: (-) COSTOS DE PRODUCCION | H13: =+I13/$I$11 -> 0.32455249 | I13: =+SUM('COSTOS Y GASTOS FEBRERO 2026'!I4:I87)*H12 -> 9.348998e+08
C14: (-) GASTOS OPERATIVOS | D14: =+E14/$E$11 -> 0.013569866 | E14: =+SUM('COSTOS Y GASTOS FEBRERO 2026'!I88:I106)*D12 -> 39089099 | G14: (-) GASTOS OPERATIVOS | H14: =+I14/$I$11 -> 0.014725691 | I14: =+SUM('COSTOS Y GASTOS FEBRERO 2026'!I88:I106)*H12 -> 42418548
C15: (=) UTILIDAD OPERACIONAL | D15: =+E15/$E$11 -> 0.16692775 | E15: =+E12-E13-E14 -> 4.8084892e+08 | G15: (=) UTILIDAD OPERACIONAL | H15: =+I15/$I$11 -> 0.18114596 | I15: =+I12-I13-I14 -> 5.2180565e+08
C16: (-) REGALIAS ANH (8%) | D16: =+E16/$E$11 -> 0.038366068 | E16: =+E12*8% -> 1.1051657e+08 | G16: (-) REGALIAS ANH (8%) | H16: =+I16/$I$11 -> 0.041633932 | I16: =+I12*8% -> 1.1992992e+08
C17: (=) UTILIDAD BRUTA | D17: =+E17/$E$11 -> 0.12856168 | E17: =+E15-E16 -> 3.7033235e+08 | G17: (=) UTILIDAD BRUTA | H17: =+I17/$I$11 -> 0.13951203 | I17: =+I15-I16 -> 4.0187573e+08
C19: RETORNO A LA INVERSION (KIMBO) | G19: UTILIDAD BRUTA CALICHE
C20: CONCEPTO | D20: VALOR | G20: CONCEPTO | H20: VALOR
C21: UTILIDAD BRUTA | D21: =+E17 -> 3.7033235e+08 | G21: UTILIDAD BRUTA | H21: =I17 -> 4.0187573e+08
C22: PORCENTAJE PARA RECUPERACION | D22: 0.3 | G22: PORCENTAJE POR CONTRATO | H22: 0.3
C23: ABONO PARA RECUPERACION | D23: =+D21*D22 -> 1.110997e+08 | G23: GANANCIA TOTAL | H23: =+(H21*H22) -> 1.2056272e+08
C24: SALDO INVERSION | D24: =+'BALANCE ENERO 2026'!D28 -> 1.1418319e+10
C25: SALDO PENDIENTE POR RECUPERAR | D25: =+D24-D23 -> 1.1307219e+10
C29: Categoria | D29: Total | E29: Porcentaje
C30: Nominas y prestaciones (Nominas, Examenes medicos, dotacion, seguridad social) | D30: 611655009 | E30: 0.32570762
C31: Servicios Integrales (Multiples servicios para el desarrollo de la operación en campo) | D31: 257412993 | E31: 0.13707298
C32: Arrendamientos Operativos | D32: 215331543 | E32: 0.11466452
C33: Equipo Petrolero | D33: 210000000 | E33: 0.11182546
C34: Servicio transporte agua de produccion | D34: 153600000 | E34: 0.081792334
C35: Combustible | D35: 111868622 | E35: 0.059570285
C36: Caja menor campo | D36: 84000000 | E36: 0.044730183
C37: Provision Recursos Humanos | D37: 50105611 | E37: 0.026681347
C38: Comunidades | D38: 50000000 | E38: 0.026625109
C39: Repuestos Generales | D39: 31419716 | E39: 0.016731067
C40: Honorarios Administrativos | D40: 22627930 | E40: 0.012049422
C41: Arrendamientos Administrativos | D41: 17044019 | E41: 0.0090759772
... C47: Total general | D47: 1.8779266e+09 | E47: 1

Sheet COSTOS Y GASTOS FEBRERO 2026
D3: Proveedor | E3: concepto | F3: Categoria | G3: Fecha de Facturacion | H3: Numero de factura | I3: Monto | J3: Estado | K3: Fecha de pago | L3: Tipo
D4: AGOFER SAS | E4: Insumos campo | F4: Repuestos Generales | G4: 46049 | H4: Orden de compra 260128 | I4: 2023488 | J4: PAGADA | K4: 46056 | L4: CP
D5: Alfonso Morales | E5: Legalizacion gastos | F5: Servicios Integrales (Multiples servicios para el desarrollo de la operación en campo) | G5: 46002 | H5: Legalizacion 03-02-2026 | I5: 9486075 | J5: PAGADA | K5: 46056 | L5: CP
D6: CALZADO LABORAL S.A.S | E6: Dotacion | F6: Nominas y prestaciones (Nominas, Examenes medicos, dotacion, seguridad social) | G6: 46051 | H6: Orden de compra 260137 | I6: 928200 | J6: PAGADA | K6: 46056 | L6: CP
D7: CAMPAMENTOS CASANARE | F7: Arrendamientos Operativos | G7: 45981 | H7: A 3504 | I7: 29987143 | J7: PAGADA | K7: 46056 | L7: CP
D8: CHARWELD E.U | E8: Renta cargadero DIC -2025 | F8: Arrendamientos Operativos | G8: 46019 | H8: FEV 1267 | I8: 9591400 | J8: PAGADA | K8: 46056 | L8: CP
D9: CODIFER SAS | E9: Insumos campo | F9: Repuestos Generales | G9: 46049 | H9: Orden de compra 260131 | I9: 9157692 | J9: PAGADA | K9: 46056 | L9: CP
D10: DON DOTACION | E10: Dotacion | F10: Nominas y prestaciones (Nominas, Examenes medicos, dotacion, seguridad social) | G10: 46055 | H10: Orden de compra 260201 | I10: 577150 | J10: PAGADA | K10: 46056 | L10: CP
D11: EMMANUEL DOTACIONES | E11: Dotacion | F11: Nominas y prestaciones (Nominas, Examenes medicos, dotacion, seguridad social) | G11: 46048 | H11: CT1 7699 | I11: 1350000 | J11: PAGADA | K11: 46056 | L11: CP
D12: FIGURADOS DEL CASANARE S.A.S | E12: Insumos campo | F12: Insumos ferreteria | G12: 46050 | H12: Orden de compra 260136 | I12: 6849500 | J12: PAGADA | K12: 46056 | L12: CP
D13: COOTRARIPORO LTDA | E13: Transporte de material de cantera para el mantenimiento de vía san Luis del Ariporo - totumo, municipio de paz de Ariporo, | F13: Mantenimiento vias (Transportes de maquinaria, materiales de cantera, irrigacion via) | G13: 46010 | H13: FE 3657 | I13: 14119344 | J13: PAGADA | K13: 46057 | L13: CP
D14: ELOGY TECNOLOGIA ECOLOGICA S.A.S | E14: Tratamiento y disposicion final de agua residuos | F14: Servicios Integrales (Multiples servicios para el desarrollo de la operación en campo) | G14: 46014 | H14: ELEC 1081 | I14: 1666690 | J14: PAGADA | K14: 46057 | L14: CP
D15: INDETRO INGENIERIA LTDA | E15: ALQUILER DE 4 TANQUES HORIZONTALES 500 BBL, DEL 01 DE NOVIEMBRE AL 30 DE NOVIEMBRE 2025, ALQUILER 2 PLATAFORMAS 01 DE NOVIEMBRE AL 30 DE NOVIEMBRE 2025 | F15: Arrendamientos Operativos | G15: 46004 | H15: FV 7953 | I15: 20706000 | J15: PAGADA | K15: 46057 | L15: CP
D16: INGENIERIA SEGURIDAD SALUD AMBIENTE S.A.S | E16: Trabajador autorizado | F16: Servicios Integrales (Multiples servicios para el desarrollo de la operación en campo) | G16: 46006 | H16: FIIG 1630 | I16: 4250000 | J16: PAGADA | K16: 46057 | L16: CP
D17: Jose del Carmen Rojas | E17: Insumos campo | F17: Insumos ferreteria | G17: 46014 | H17: N 50159 | I17: 1512500 | J17: PAGADA | K17: 46057 | L17: CP
D18: Jose del Carmen Rojas | E18: Insumos campo | F18: Insumos ferreteria | G18: 46015 | H18: N 50166 | I18: 50000 | J18: PAGADA | K18: 46057 | L18: CP
D19: Jose James Correa | E19: Alquiler vehiculo OCT -2025 | F19: Arrendamientos Operativos | G19: 45973 | H19: Cuenta de cobro 001 2025 | I19: 4000000 | J19: PAGADA | K19: 46057 | L19: CP
... D52: SERVICIOS DE INSPECCION Y MANTENIMIENTO EN INGENIERIAS SAS | E52: AFORO TANQUE VERTICAL - AFORO EN TANQUES HORIZONTALES - CALIBRACIÓN DE TANQUE HORIZONTAL Y VERTICAL UBICADOS EN LA PLATAFORMA KIMBO BLOQUE JOROPO | F52: Servicios Integrales (Multiples servicios para el desarrollo de la operación en campo) | G52: 46059 | H52: SIM 699 | I52: 25379725 | J52: PAGADA | K52: 46065 | L52: CP
D53: SEGURIDAD SOCIAL | E53: 46054 | F53: Nominas y prestaciones (Nominas, Examenes medicos, dotacion, seguridad social) | G53: 46066 | H53: - | I53: 123382600 | J53: PAGADA | K53: 46067 | L53: CP
D54: Wilson Belisario Martinez | E54: Trasnporte de carga | F54: Servicios Integrales (Multiples servicios para el desarrollo de la operación en campo) | G54: 46064 | H54: FE 105 | I54: 5000000 | J54: PAGADA | K54: 46067 | L54: CP
D55: NOMINA | E55: Nomina Operativa | F55: Nominas y prestaciones (Nominas, Examenes medicos, dotacion, seguridad social) | G55: 46068 | H55: primera quincena febrero 2026 | I55: 216522792 | J55: PAGADA | K55: 46068 | L55: CP
D56: Claudia Yaneth Becerra | E56: Transporte de carga | F56: Servicios Integrales (Multiples servicios para el desarrollo de la operación en campo) | G56: 46063 | H56: Cuenta de Cobro 001 | I56: 5000000 | J56: PAGADA | K56: 46070 | L56: CP
D57: MATERIALES ELECTRICOS V M S.A.S | E57: Insumos campo | F57: Repuestos Generales | G57: 46058 | H57: Orden de compra 260226 | I57: 3522985 | J57: PAGADA | K57: 46070 | L57: CP
D58: Hector Draulio Martinez | E58: Movilizacion combustible | F58: Servicios Integrales (Multiples servicios para el desarrollo de la operación en campo) | G58: 46062 | H58: Cuenta de cobro 58 | I58: 5530000 | J58: PAGADA | K58: 46071 | L58: CP
D59: CODIFER SAS | E59: Insumos campo | F59: Repuestos Generales | G59: 46066 | H59: Orden de compra 260223 | I59: 2447681 | J59: PAGADA | K59: 46071 | L59: CP
D60: MUNDIAL DE TORNILLOS S.A | E60: Insumos campo | F60: Insumos ferreteria | G60: 46066 | H60: Orden de compra 260225 | I60: 693715 | J60: PAGADA | K60: 46071 | L60: CP
D61: Luz Jareth Rodriguez Rodriguez | E61: Transporte de carga | F61: Servicios Integrales (Multiples servicios para el desarrollo de la operación en campo) | G61: 46064 | H61: Cuenta de Cobro 001 | I61: 1500000 | J61: PAGADA | K61: 46071 | L61: CP
D62: Martha Duralva Riay | E62: Transporte de grua | F62: Servicios Integrales (Multiples servicios para el desarrollo de la operación en campo) | G62: 46065 | H62: Cuenta de Cobro 202501124 | I62: 16600000 | J62: PAGADA | K62: 46071 | L62: CP
D63: PETROREPUESTOS | E63: Insumos campo | F63: Repuestos de Equipo Petrolero | G63: 46008 | H63: FAC 3748 | I63: 1229270 | J63: PAGADA | K63: 46073 | L63: CP
D64: CAMPAMENTOS CASANARE | F64: Arrendamientos Operativos | G64: 46037 | H64: A 3610 | I64: 33201000 | J64: PAGADA | K64: 46073 | L64: CP
D65: PETROREPUESTOS | E65: Insumos campo | F65: Repuestos de Equipo Petrolero | G65: 46038 | H65: FAC 3753 | I65: 4298875 | J65: PAGADA | K65: 46073 | L65: CP
D66: PETROREPUESTOS | E66: Insumos campo | F66: Repuestos de Equipo Petrolero | G66: 46041 | H66: FACT 3754 | I66: 314160 | J66: PAGADA | K66: 46073 | L66: CP
D67: PETROREPUESTOS | E67: Insumos campo | F67: Repuestos de Equipo Petrolero | G67: 46050 | H67: FAC 3757 | I67: 3001085 | J67: PAGADA | K67: 46073 | L67: CP
D68: MONTACARGAS NACIONALES S.A.S | E68: Servicio alquiler mini cargador | F68: Arrendamientos Operativos | G68: 46071 | H68: MNDL 3341 | I68: 5355000 | J68: PAGADA | K68: 46073 | L68: CP
D69: Martha Duralva Riay | E69: Transporte de carga | F69: Servicios Integrales (Multiples servicios para el desarrollo de la operación en campo) | G69: 46070 | H69: Cuenta de Cobro 20250129 | I69: 1200000 | J69: PAGADA | K69: 46073 | L69: CP
D70: CALZADO LABORAL S.A.S | E70: Dotacion | F70: Nominas y prestaciones (Nominas, Examenes medicos, dotacion, seguridad social) | G70: 46069 | H70: Orden de compra 260227 | I70: 618800 | J70: PAGADA | K70: 46073 | L70: CP
D71: CASA DE LA GUADAÑA PYP AGRO S.A.S | E71: Insumos campo | F71: Repuestos Generales | G71: 46064 | H71: FE 18317 | I71: 553000 | J71: PAGADA | K71: 46073 | L71: CP
D72: DON DOTACION | E72: Dotacion | F72: Nominas y prestaciones (Nominas, Examenes medicos, dotacion, seguridad social) | G72: 46070 | H72: Orden de compra 260228 | I72: 177310 | J72: PAGADA | K72: 46073 | L72: CP
D73: MONCHE DIMAS PLAZAS | E73: Pago avaluo comercial de servidumbre rural | F73: Servicios Integrales (Multiples servicios para el desarrollo de la operación en campo) | G73: 46073 | H73: Cuenta de Cobro 001 | I73: 4000000 | J73: PAGADA | K73: 46073 | L73: CP
D74: EMPAQUETADURAS Y EMPAQUES S.A | E74: Insumos campo | F74: Insumos ferreteria | G74: 46076 | H74: Orden de compra 260235 | I74: 2713200 | J74: PAGADA | K74: 46076 | L74: CP
...

Sheet BALANCE MARZO 2026
C3: TOTAL BARRILES PRODUCIDOS KIMBO MARZO 2026 (FORMAS DE PRODUCCION FISCALIZADAS ANH) | D3: 8725.89
C4: TOTAL BARRILES PRODUCIDOS CALICHE MARZO 2026 (FORMAS DE PRODUCCION FISCALIZADAS ANH) | D4: 9749.67
C5: PRECIO PROMEDIO DE VENTA BRENT MARZO 2026 | D5: 77.595
C6: TRM PROMEDIO MARZO 2026 | D6: ='COSTOS Y GASTOS MARZO 2026'!E195 -> 3717.5574
C8: BALANCE KIMBO MARZO 2026 | G8: BALANCE CALICHE MARZO 2026
C9: CONCEPTO | D9: PROPORCION SOBRE EL INGRESO TOTAL | E9: MONTO (COP) | G9: CONCEPTO | H9: PROPORCION SOBRE EL INGRESO TOTAL | I9: MONTO (COP)
C11: INGRESO TOTAL | E11: =+SUM(D3:D4)*D5*D6 -> 5.3295315e+09 | G11: INGRESO TOTAL | I11: =+SUM(D3:D4)*D5*D6 -> 5.3295315e+09
C12: INGRESOS POR VENTAS KIMBO | D12: =+E12/E11 -> 0.47229367 | E12: =+D3*D5*D6 -> 2.517104e+09 | G12: INGRESOS POR VENTAS CALICHE | H12: =+I12/I11 -> 0.52770633 | I12: =+D4*D5*D6 -> 2.8124275e+09
C13: (-) COSTOS DE PRODUCCION | D13: =+E13/$E$11 -> 0.24111868 | E13: =+SUM('COSTOS Y GASTOS MARZO 2026'!I3:I137)*D12 -> 1.2850496e+09 | G13: (-) COSTOS DE PRODUCCION | H13: =+I13/$I$11 -> 0.26940834 | I13: =+SUM('COSTOS Y GASTOS MARZO 2026'!I3:I137)*H12 -> 1.4358203e+09
C14: (-) GASTOS OPERATIVOS | D14: =+E14/$E$11 -> 0.0060736749 | E14: =+SUM('COSTOS Y GASTOS MARZO 2026'!I138:I161)*D12 -> 32369841 | G14: (-) GASTOS OPERATIVOS | H14: =+I14/$I$11 -> 0.0067862792 | I14: =+SUM('COSTOS Y GASTOS MARZO 2026'!I138:I161)*H12 -> 36167689
C15: (=) UTILIDAD OPERACIONAL | D15: =+E15/$E$11 -> 0.22510131 | E15: =+E12-E13-E14 -> 1.1996845e+09 | G15: (=) UTILIDAD OPERACIONAL | H15: =+I15/$I$11 -> 0.25151171 | I15: =+I12-I13-I14 -> 1.3404396e+09
C16: (-) REGALIAS ANH (8%) | D16: =+E16/$E$11 -> 0.037783493 | E16: =+E12*8% -> 2.0136832e+08 | G16: (-) REGALIAS ANH (8%) | H16: =+I16/$I$11 -> 0.042216507 | I16: =+I12*8% -> 2.249942e+08
C17: (=) UTILIDAD BRUTA | D17: =+E17/$E$11 -> 0.18731782 | E17: =+E15-E16 -> 9.9831622e+08 | G17: (=) UTILIDAD BRUTA | H17: =+I17/$I$11 -> 0.2092952 | I17: =+I15-I16 -> 1.1154454e+09
C19: RETORNO A LA INVERSION (KIMBO) | G19: UTILIDAD BRUTA CALICHE
C20: CONCEPTO | D20: VALOR | G20: CONCEPTO | H20: VALOR
C21: UTILIDAD BRUTA | D21: =+E17 -> 9.9831622e+08 | G21: UTILIDAD BRUTA | H21: =I17 -> 1.1154454e+09
C22: PORCENTAJE PARA RECUPERACION | D22: 0.3 | G22: PORCENTAJE POR CONTRATO | H22: 0.3
C23: ABONO PARA RECUPERACION | D23: =+D21*D22 -> 2.9949487e+08 | G23: GANANCIA TOTAL | H23: =+(H21*H22) -> 3.3463361e+08
C24: SALDO INVERSION | D24: ='BALANCE FEBRERO 2026'!D25 -> 1.1307219e+10
C25: SALDO PENDIENTE POR RECUPERAR | D25: =+D24-D23 -> 1.1007725e+10
C28: Categoria | D28: Total | E28: Porcentaje
C29: Nominas y prestaciones (Nominas, examenes medicos, dotacion, seguridad social) | D29: 618053327 | E29: 0.22157155
C30: Equipo Petrolero | D30: 420487500 | E30: 0.15074438
C31: Arrendamientos Operativos | D31: 392880070 | E31: 0.14084715
C32: Servicios Integrales (Multiples servicios para el desarrollo de la operación en campo) | D32: 286222557 | E32: 0.10261053
C33: Servicio transporte agua de produccion | D33: 272700000 | E33: 0.097762701
C34: Quimicos (Quimicos Generales, Quimicos para producción, productos de aseo) | D34: 188697589 | E34: 0.067647913
C35: Mantenimiento vias (Transportes de maquinaria, materiales de cantera, irrigacion via) | D35: 179490224 | E35: 0.064347081
C36: Combustible | D36: 111452000 | E36: 0.03995544
C37: Caja menor campo | D37: 104320000 | E37: 0.037398625
C38: Provisiones Recursos Humanos | D38: 51003916 | E38: 0.018284857
C39: Comunidades | D39: 50000000 | E39: 0.017924954
C40: Provision equipo petrolero | D40: 26647658 | E40: 0.0095531609
... C49: Total general | D49: 2.7894074e+09 | E49: 1

Sheet COSTOS Y GASTOS MARZO 2026
D2: Proveedor | E2: concepto | F2: Categoria | G2: Fecha de Facturacion | H2: Numero de factura | I2: Monto | J2: Estado | K2: Fecha de pago | L2: Tipo
D3: AGOFER S.A.S | E3: Insumos campo | F3: Repuestos Generales | G3: 46083 | H3: Orden de compra 260303 | I3: 2143916 | J3: PAGADA | K3: 46083 | L3: CP
D4: AGREGADOS PETREOS DEL ARIPORO | E4: Transporte agua crudo | F4: Servicio transporte agua de produccion | G4: 46032 | H4: FE 879 | I4: 118400000 | J4: PAGADA | K4: 46083 | L4: CP
D5: CODIFER SAS | E5: Insumos campo | F5: Repuestos Generales | G5: 46083 | H5: Orden de compra 260304 | I5: 481793 | J5: PAGADA | K5: 46083 | L5: CP
D6: ESTANDAR OIL SAS | E6: Alquiler frac tank (01 DIC al 31 de DIC 2025) | F6: Arrendamientos Operativos | G6: 46030 | H6: STFE 30 | I6: 28036400 | J6: PAGADA | K6: 46083 | L6: CP
D7: ESTANDAR OIL SAS | E7: Alquiler tanques horizontales (01 DIC al 31 de DIC 2025) | F7: Arrendamientos Operativos | G7: 46030 | H7: STFE 31 | I7: 30987600 | J7: PAGADA | K7: 46083 | L7: CP
D8: ESTANDAR OIL SAS | E8: Alquiler tanques verticales (01 DIC al 31 de DIC 2025) | F8: Arrendamientos Operativos | G8: 46030 | H8: STFE 32 | I8: 49063700 | J8: PAGADA | K8: 46083 | L8: CP
D9: ESTANDAR OIL SAS | E9: Alquiler gun barrel (01 DIC al 31 de DIC 2025) | F9: Arrendamientos Operativos | G9: 46030 | H9: STFE 33 | I9: 19182800 | J9: PAGADA | K9: 46083 | L9: CP
D10: FERRETERIA ELI | E10: Insumos campo | F10: Insumos Ferreteria | G10: 46043 | H10: Orden de compra 260120 | I10: 450000 | J10: PAGADA | K10: 46083 | L10: CP
D11: FORPETROIL S.A.S | E11: RENTA TANQUE HORIZONTAL - RENTA GENERADOR (01 de DIC al 31 DIC 2025) - CASETA DORMITORIO ( 01 de DIC al 31 DIC 2025) - CASETA COMPANY ( 01 de DIC al 31 DIC 2025) - UNIDAD DE BOMBEO ( 01 de DIC al 31 DIC 2025) | F11: Arrendamientos Operativos | G11: 46043 | H11: FACT 7 | I11: 81526900 | J11: PAGADA | K11: 46083 | L11: CP
D12: INDETRO INGENIERIA LTDA | E12: ALQUILER DE 4 TANQUES HORIZONTALES 500 BBL (DEL 01 DE DICIEMBRE AL 31 DE DICIEMBRE 2025) ALQUILER 2 PLATAFORMAS ( DEL 01 DE DICIEMBRE AL 31 DE DICIEMBRE 2025) | F12: Arrendamientos Operativos | G12: 46004 | H12: FV 7954 | I12: 21396200 | J12: PAGADA | K12: 46083 | L12: CP
D13: Jose del Carmen Rojas | E13: Insumos campo | F13: Insumos Ferreteria | G13: 46037 | H13: N 50667 | I13: 2470000 | J13: PAGADA | K13: 46083 | L13: CP
D14: Jose del Carmen Rojas | E14: Insumos campo | F14: Insumos Ferreteria | G14: 46037 | H14: N 50668 | I14: 507000 | J14: PAGADA | K14: 46083 | L14: CP
... D84: AGREGADOS PETREOS DEL ARIPORO | E84: Transporte material | F84: Mantenimiento vias (Transportes de maquinaria, materiales de cantera, irrigacion via) | G84: 46037 | H84: FE 880 | I84: 18162936 | J84: PAGADA | K84: 46107 | L84: CP
D85: CAMPAMENTOS CASANARE | F85: Arrendamientos Operativos | G85: 46067 | H85: A 3653 | I85: 34143837 | J85: PAGADA | K85: 46107 | L85: CP
D86: CHARWELD E.U | E86: Alquiler cargadero ENE 2026 | F86: Arrendamientos Operativos | G86: 46056 | H86: FEV 1269 | I86: 9591400 | J86: PAGADA | K86: 46107 | L86: CP
D87: Cipriana Fernandez de Garcia | E87: Alimentacion personal de campo | F87: Servicios Integrales (Multiples servicios para el desarrollo de la operación en campo) | G87: 46069 | H87: Cuenta de Cobro 008 | I87: 6480000 | J87: PAGADA | K87: 46107 | L87: CP
D88: Diego Alejandro Camacho | E88: Transporte montacarga | F88: Servicios Integrales (Multiples servicios para el desarrollo de la operación en campo) | G88: 46073 | H88: Cuenta de Cobro 0026 | I88: 5000000 | J88: PAGADA | K88: 46107 | L88: CP
D89: Elbis Acosta Prada | E89: Alquiler vehiculo | F89: Arrendamientos Operativos | G89: 46071 | H89: EAP 20 | I89: 12000000 | J89: PAGADA | K89: 46107 | L89: CP
D90: ELOGY TECNOLOGIA ECOLOGICA S.A.S | E90: Tratamiento y disposicion final agua | F90: Servicios Integrales (Multiples servicios para el desarrollo de la operación en campo) | G90: 46052 | H90: ELEC 1112 | I90: 103730 | J90: PAGADA | K90: 46107 | L90: CP
D91: ELOGY TECNOLOGIA ECOLOGICA S.A.S | E91: Tratamiento y disposicion final de residuos contaminados | F91: Servicios Integrales (Multiples servicios para el desarrollo de la operación en campo) | G91: 46073 | H91: ELEC 1124 | I91: 2322940 | J91: PAGADA | K91: 46107 | L91: CP
D92: ELOGY TECNOLOGIA ECOLOGICA S.A.S | E92: Tratamiento y disposicion final de tierras contaminadas | F92: Servicios Integrales (Multiples servicios para el desarrollo de la operación en campo) | G92: 46072 | H92: ELEC 1123 | I92: 3040968 | J92: PAGADA | K92: 46107 | L92: CP
D93: ENVIOIL ENVIROMENTAL OIL SERVICES S.A.S | E93: Tratamiento y disposicion final de agua | F93: Servicios Integrales (Multiples servicios para el desarrollo de la operación en campo) | G93: 46048 | H93: ENVI 95 | I93: 34717942 | J93: PAGADA | K93: 46107 | L93: CP
D94: ESTRATEGIA Y SERVICIO COLOMBIA DE TRANSPORTE S.A.S | E94: Insumos campo | F94: Servicios Integrales (Multiples servicios para el desarrollo de la operación en campo) | G94: 46041 | H94: FELE 317 | I94: 9772400 | J94: PAGADA | K94: 46107 | L94: CP
D95: GANADERIA Y TRANSPORTE HERMANOS LOPEZ CASALLAS S.A.S | E95: Trasporte de Agua para Irrigacion de la via donde transitan las mulas | F95: Mantenimiento vias (Transportes de maquinaria, materiales de cantera, irrigacion via) | G95: 46056 | H95: FE 103 | I95: 26350000 | J95: PAGADA | K95: 46107 | L95: CP
D96: GANADERIA Y TRANSPORTE HERMANOS LOPEZ CASALLAS S.A.S | E96: Trasporte de Agua para Irrigacion de la via donde transitan las mulas | F96: Mantenimiento vias (Transportes de maquinaria, materiales de cantera, irrigacion via) | G96: 46056 | H96: FE 102 | I96: 26350000 | J96: PAGADA | K96: 46107 | L96: CP
D97: GANADERIA Y TRANSPORTE HERMANOS LOPEZ CASALLAS S.A.S | E97: Trasporte de Agua para Irrigacion de la via donde transitan las mulas | F97: Mantenimiento vias (Transportes de maquinaria, materiales de cantera, irrigacion via) | G97: 46036 | H97: FE 96 | I97: 26350000 | J97: PAGADA | K97: 46107 | L97: CP
... D125: INGENII CONSULTANTS S.A.S | E125: Inspeccion tuberia | F125: Servicios Integrales (Multiples servicios para el desarrollo de la operación en campo) | G125: 46101 | H125: Orden de servicio 260330 | I125: 16085100 | J125: PAGADA | K125: 46111 | L125: CP
D126: GASTOS DE CAJA MENOR CAMPO | E126: 46082 | F126: Caja menor campo | G126: - | H126: - | I126: 104320000 | J126: PAGADA | K126: 46111 | L126: CP
D127: HANNA INSTRUMENTS S.A.S | E127: Bomba de aire | F127: Servicios Integrales (Multiples servicios para el desarrollo de la operación en campo) | G127: 46111 | H127: Orden de compra 260341 | I127: 787768 | J127: PAGADA | K127: 46111 | L127: CP
D128: ALCA LTDA | E128: Lavadoras | F128: Repuestos Generales | G128: 46111 | H128: Orden de compra 260340 | I128: 1568000 | J128: PAGADA | K128: 46111 | L128: CP
D129: DON DOTACION | E129: Dotacion | F129: Nominas y prestaciones (Nominas, examenes medicos, dotacion, seguridad social) | G129: 46108 | H129: Orden de compra 260339 | I129: 2270044 | J129: PAGADA | K129: 46111 | L129: CP
D130: INGENII CONSULTANTS S.A.S | E130: Inspeccion gases combustion | F130: Servicios Integrales (Multiples servicios para el desarrollo de la operación en campo) | G130: 46111 | H130: INGE 58 | I130: 7735000 | J130: PAGADA | K130: 46111 | L130: CP
D131: TALECTRO INGENIERIA S.A.S | E131: Tacometro | F131: Insumos Ferreteria | G131: 46111 | H131: Orden de compra 260342 | I131: 595000 | J131: PAGADA | K131: 46111 | L131: CP
D132: IMPOFER IMPORTADORA DE FERRETERIA S.A.S | E132: Insumos campo | F132: Repuestos Generales | G132: 46111 | H132: Orden de compra 260343 | I132: 599760 | J132: PAGADA | K132: 46111 | L132: CP
D133: Fabian Rene Solano | E133: Transporte cargadero | F133: Servicios Integrales (Multiples servicios para el desarrollo de la operación en campo) | G133: 46110 | H133: Cuenta de cobro 002 2026 | I133: 2700000 | J133: PAGADA | K133: 46111 | L133: CP
D134: Comunidades | E134: 46082 | F134: Comunidades | G134: - | H134: - | I134: 50000000 | J134: PAGADA | K134: 46111 | L134: CP
D135: NOMINA | E135: Nomina Operativa | F135: Nominas y prestaciones (Nominas, examenes medicos, dotacion, seguridad social) | G135: 46111 | H135: Segunda quincena marzo 2026 | I135: 235386891 | J135: PAGADA | K135: 46111 | L135: CP
D136: PROVISIONES RECURSOS HUMANOS | E136: 46082 | F136: Provisiones Recursos Humanos | G136: 46111 | H136: - | I136: 51003916 | J136: PAGADA | K136: 46111 | L136: CP
D137: PROVISION PROPIEDAD PLANTA Y EQUIPO | E137: 46082 | F137: Provision equipo petrolero | G137: 46111 | H137: - | I137: =0.5%*'BALANCE MARZO 2026'!E11 -> 26647658 | J137: PAGADA | K137: 46052 | L137: CP
...

Sheet BALANCE ABRIL 2026
C3: TOTAL BARRILES PRODUCIDOS KIMBO ABRIL 2026 (FORMAS DE PRODUCCION FISCALIZADAS ANH) | D3: 7466.39
C4: TOTAL BARRILES PRODUCIDOS CALICHE ABRIL 2026 (FORMAS DE PRODUCCION FISCALIZADAS ANH) | D4: 10039.94
C5: PRECIO PROMEDIO DE VENTA BRENT ABRIL 2026 | D5: 91.23
C6: TRM PROMEDIO ABRIL 2026 | D6: ='COSTOS Y GASTOS ABRIL 2026'!D136 -> 3617.5187
C8: BALANCE KIMBO ABRIL 2026 | G8: BALANCE CALICHE ABRIL 2026
C9: CONCEPTO | D9: PROPORCION SOBRE EL INGRESO TOTAL | E9: MONTO (COP) | G9: CONCEPTO | H9: PROPORCION SOBRE EL INGRESO TOTAL | I9: MONTO (COP)
C11: INGRESO TOTAL | E11: =+SUM(D3:D4)*D5*D6 -> 5.7775481e+09 | G11: INGRESO TOTAL | I11: =+SUM(D3:D4)*D5*D6 -> 5.7775481e+09
C12: INGRESOS POR VENTAS KIMBO | D12: =+E12/E11 -> 0.42649659 | E12: =+D3*D5*D6 -> 2.4641045e+09 | G12: INGRESOS POR VENTAS CALICHE | H12: =+I12/I11 -> 0.57350341 | I12: =+D4*D5*D6 -> 3.3134435e+09
C13: (-) COSTOS DE PRODUCCION | D13: =+E13/$E$11 -> 0.15733228 | E13: =+SUM('COSTOS Y GASTOS ABRIL 2026'!H3:H87)*D12 -> 9.0899483e+08 | G13: (-) COSTOS DE PRODUCCION | H13: =+I13/$I$11 -> 0.21156231 | I13: =+SUM('COSTOS Y GASTOS ABRIL 2026'!H3:H87)*H12 -> 1.2223114e+09
C14: (-) GASTOS OPERATIVOS | D14: =+E14/$E$11 -> 0.0062190985 | E14: =+SUM('COSTOS Y GASTOS ABRIL 2026'!H88:H102)*D12 -> 35931140 | G14: (-) GASTOS OPERATIVOS | H14: =+I14/$I$11 -> 0.0083627262 | I14: =+SUM('COSTOS Y GASTOS ABRIL 2026'!H88:H102)*H12 -> 48316053
C15: (=) UTILIDAD OPERACIONAL | D15: =+E15/$E$11 -> 0.26294521 | E15: =+E12-E13-E14 -> 1.5191786e+09 | G15: (=) UTILIDAD OPERACIONAL | H15: =+I15/$I$11 -> 0.35357838 | I15: =+I12-I13-I14 -> 2.0428161e+09
C16: (-) REGALIAS ANH (8%) | D16: =+E16/$E$11 -> 0.034119727 | E16: =+E12*8% -> 1.9712836e+08 | G16: (-) REGALIAS ANH (8%) | H16: =+I16/$I$11 -> 0.045880273 | I16: =+I12*8% -> 2.6507548e+08
C17: (=) UTILIDAD BRUTA | D17: =+E17/$E$11 -> 0.22882548 | E17: =+E15-E16 -> 1.3220502e+09 | G17: (=) UTILIDAD BRUTA | H17: =+I17/$I$11 -> 0.30769811 | I17: =+I15-I16 -> 1.7777406e+09
C19: RETORNO A LA INVERSION (KIMBO) | G19: UTILIDAD BRUTA CALICHE
C20: CONCEPTO | D20: VALOR | G20: CONCEPTO | H20: VALOR
C21: UTILIDAD BRUTA | D21: =+E17 -> 1.3220502e+09 | G21: UTILIDAD BRUTA | H21: =I17 -> 1.7777406e+09
C22: PORCENTAJE PARA RECUPERACION | D22: 0.3 | G22: PORCENTAJE POR CONTRATO | H22: 0.3
C23: ABONO PARA RECUPERACION | D23: =+D21*D22 -> 3.9661506e+08 | G23: GANANCIA TOTAL | H23: =+(H21*H22) -> 5.3332218e+08
C24: SALDO INVERSION | D24: ='BALANCE MARZO 2026'!D25 -> 1.1007725e+10
C25: SALDO PENDIENTE POR RECUPERAR | D25: =+D24-D23 -> 1.0611109e+10
C28: Etiquetas de fila | D28: Total | E28: Porcentaje
C29: Nominas y prestaciones (Nominas, examenes medicos, dotacion, seguridad social) | D29: 638865940 | E29: 0.28835502
C30: Arrendamientos Operativos | D30: 441351268 | E30: 0.19920588
C31: Servicio transporte agua de produccion | D31: 327375000 | E31: 0.14776218
C32: Combustible | D32: 133741106 | E32: 0.06036465
C33: Comunidades | D33: 129992000 | E33: 0.058672474
C34: Caja menor campo | D34: 94000000 | E34: 0.042427323
C35: Servicios Integrales (Multiples servicios para el desarrollo de la operación en campo) | D35: 71693853 | E35: 0.032359343
C36: Equipo petrolero | D36: 64299203 | E36: 0.029021735
C37: Quimicos (Quimicos Generales, Quimicos para producción, productos de aseo) | D37: 55943873 | E37: 0.025250519
C38: Repuestos Generales | D38: 55360548 | E38: 0.024987232
C39: Provisiones Recursos Humanos | D39: 50699940 | E39: 0.022883646
C40: Mantenimiento vias (Transportes de maquinaria, materiales de cantera, irrigacion via) | D40: 44009700 | E40: 0.019863976
... C48: Total general | D48: 2.2155534e+09 | E48: 1

Sheet COSTOS Y GASTOS ABRIL 2026
C2: Proveedor | D2: concepto | E2: Categoria | F2: Fecha de Facturacion | G2: Numero de factura | H2: Monto | I2: Estado | J2: Fecha de pago | K2: Tipo
C3: AGREGADOS PETREOS DEL ARIPORO | D3: Transporte de agua | E3: Servicio transporte agua de produccion | F3: 46064 | G3: FE 888 | H3: 144800000 | I3: PAGADA | J3: 46113 | K3: CP
C4: TRANSPORTES MULTICARGA S.A.S | D4: Transporte agua | E4: Servicio transporte agua de produccion | F4: 46076 | G4: FETM 9586 | H4: 87200000 | I4: PAGADA | J4: 46113 | K4: CP
C5: FORPETROIL S.A.S | D5: RENTA TANQUE HORIZONTAL - RENTA GENERADOR (1 de enero al 31 de enero) - CASETA DORMITORIO (1 de enero al 31 de enero) - CASETA COMPANY (1 de enero al 31 de enero) - UNIDAD DE BOMBEO (1 de enero al 31 de enero) | E5: Arrendamientos Operativos | F5: 46080 | G5: FACT 8 | H5: 81526900 | I5: PAGADA | J5: 46113 | K5: CP
C6: PACIFIC ENERGY SOLUTIONS SAS | D6: ALQUILER DE UNIDAD DE BOMBEO - CASETA TIPO COMPANY (1 al 31 de enero 2026) - CASETA TIPO DORMITORIO (1 al 31 de enero 2026) - RENTA GENERADOR (1 al 31 de enero 2026) - RENTA TANQUE HORIZONTAL (del 1 al 31 de enero 2026) | E6: Arrendamientos Operativos | F6: 46055 | G6: PEFE 9 | H6: 81526900 | I6: PAGADA | J6: 46113 | K6: CP
C7: PETROASES GLOBAL ENERGY SAS | D7: Alquiler bomba triplex | E7: Arrendamientos Operativos | F7: 46086 | G7: FEVT 117 | H7: 19992000 | I7: PAGADA | J7: 46113 | K7: CP
C8: CHARWELD E.U | D8: Renta cargadero FEB 2026 | E8: Arrendamientos Operativos | F8: 46085 | G8: FEV 1271 | H8: 8663200 | I8: PAGADA | J8: 46113 | K8: CP
C9: FERRETERIA ELI | D9: Insumos campo | E9: Insumos Ferreteria | F9: 46092 | G9: ZELI 12896 | H9: 4329000 | I9: PAGADA | J9: 46113 | K9: CP
C10: Marcelo Rojas Ballesteros | D10: Consultoria juridica | E10: Honorarios Operativos | F10: 46093 | G10: Cuenta de Cobro 011 | H10: 4000000 | I10: PAGADA | J10: 46113 | K10: CP
C11: PETROREPUESTOS | D11: Insumos campo | E11: Repuestos de Equipo Petrolero | F11: 46084 | G11: FAC 3771 | H11: 2578254 | I11: PAGADA | J11: 46113 | K11: CP
C12: FERRETERIA ELI | D12: Transporte escombros | E12: Servicios Integrales (Multiples servicios para el desarrollo de la operación en campo) | F12: 46092 | G12: ZELI 12918 | H12: 1750000 | I12: PAGADA | J12: 46113 | K12: CP
C13: COOPERATIVA MULTIACTIVA DE INVERSIONES INGENIERIA Y TRANSPORTES | D13: Transporte material | E13: Mantenimiento vias (Transportes de maquinaria, materiales de cantera, irrigacion via) | F13: 46090 | G13: FET 259 | H13: 1710816 | I13: PAGADA | J13: 46113 | K13: CP
C14: FERRETERIA ELI | D14: Transporte material | E14: Mantenimiento vias (Transportes de maquinaria, materiales de cantera, irrigacion via) | F14: 46111 | G14: ZELI 13452 | H14: 1704000 | I14: PAGADA | J14: 46113 | K14: CP
C15: Luz Jareth Rodriguez Rodriguez | D15: Transporte camioneta | E15: Servicios Integrales (Multiples servicios para el desarrollo de la operación en campo) | F15: 46105 | G15: Cuenta de cobro 002 | H15: 500000 | I15: PAGADA | J15: 46113 | K15: CP
C16: INVERSIONES RIVEROS SAS | D16: ACPM | E16: Combustible | F16: - | G16: - | H16: 133741106 | I16: PAGADA | J16: 46113 | K16: CP
C17: ESTANDAR OIL SAS | D17: Bomba Jet | E17: Equipo petrolero | F17: 46079 | G17: STFE 38 | H17: 52955000 | I17: PAGADA | J17: 46114 | K17: CP
C18: ESTANDAR OIL SAS | D18: Alquiler tanques verticales (1 al 31 de enero 2026) | E18: Arrendamientos Operativos | F18: 46062 | G18: STFE 36 | H18: 49063700 | I18: PAGADA | J18: 46114 | K18: CP
C19: ESTANDAR OIL SAS | D19: Alquiler tanques horizontales (1 al 31 de enero 2026) | E19: Arrendamientos Operativos | F19: 46062 | G19: STFE 35 | H19: 30987600 | I19: PAGADA | J19: 46114 | K19: CP
C20: ESTANDAR OIL SAS | D20: Alquiler frac tank (1 al 31 de enero 2026) | E20: Arrendamientos Operativos | F20: 46062 | G20: STFE 34 | H20: 28036400 | I20: PAGADA | J20: 46114 | K20: CP
C21: ESTANDAR OIL SAS | D21: Alquiler gun barrel (1 al 31 de enero 2026) | E21: Arrendamientos Operativos | F21: 46062 | G21: STFE 37 | H21: 19182800 | I21: PAGADA | J21: 46114 | K21: CP
C22: ALDEMAR GUZMAN E HIJOS S.A.S | D22: Dotacion | E22: Nominas y prestaciones (Nominas, examenes medicos, dotacion, seguridad social) | F22: 46118 | G22: Orden de compra 260408 | H22: 1053150 | I22: PAGADA | J22: 46119 | K22: CP
C23: MANGUERAS Y RACORES | D23: Insumos campo | E23: Repuestos de Equipo Petrolero | F23: 46118 | G23: Orden de compra 260404 | H23: 330000 | I23: PAGADA | J23: 46119 | K23: CP
C24: Ferlin Pena Marin | D24: Planta eco diesel | E24: Servicios Integrales (Multiples servicios para el desarrollo de la operación en campo) | F24: 46121 | G24: FEL 1278 | H24: 5850000 | I24: PAGADA | J24: 46121 | K24: CP
C25: TECNOLOGIA, DISENO Y MANTENIMIENTO DE COLOMBIA S.A.S | D25: Reparacion electrobomba | E25: Servicios Integrales (Multiples servicios para el desarrollo de la operación en campo) | F25: 46119 | G25: FETD 321 | H25: 1666000 | I25: PAGADA | J25: 46121 | K25: CP
C26: INGEPROYECTOS L & C S.A.S | D26: Alquiler taladro percutor makita 2 días | E26: Arrendamientos Operativos | F26: 46120 | G26: LC 135 | H26: 166600 | I26: PAGADA | J26: 46121 | K26: CP
C27: NOVATEC FLUIDS SYSTEM SA | D27: BOMBA DOSIFICADORA ELECTROMAGNÉTICA DE DIAFRAGMA MARCA:LIQUID METRONICS / MILTON ROY | E27: Equipo petrolero | F27: 46120 | G27: Orden de compra 260407 | H27: 11344203 | I27: PAGADA | J27: 46121 | K27: CP
C28: Martha Duralva Riay | D28: Transporte tanque de pozo ODT a KIMBO y de pozo KIMBO a ODT | E28: Servicios Integrales (Multiples servicios para el desarrollo de la operación en campo) | F28: 46119 | G28: Cuenta de cobro 004 | H28: 12000000 | I28: PAGADA | J28: 46122 | K28: CP
... C34: LEDSCOLOR LAT | D34: Insumos campo | E34: Repuestos Generales | F34: 46121 | G34: Orden de compra 260409 | H34: 224000 | I34: PAGADA | J34: 46124 | K34: CP
C35: CAMPAMENTOS CASANARE | E35: Arrendamientos Operativos | F35: 46088 | G35: A 3691 | H35: 32567968 | I35: PAGADA | J35: 46126 | K35: CP
C36: Romulo Alberto Camargo | D36: Transporte de agua | E36: Servicio transporte agua de produccion | F36: 46084 | G36: AC 344 | H36: 23375000 | I36: PAGADA | J36: 46126 | K36: CP
C37: CUMMINS DE LOS ANDES S.A | D37: Insumos campo | E37: Repuestos Generales | F37: 46119 | G37: Orden de compra 260412 | H37: 16450003 | I37: PAGADA | J37: 46126 | K37: CP
C38: Carlos Fernando Moreno | D38: Consultoria para creacion anexos cartograficos | E38: Servicios Integrales (Multiples servicios para el desarrollo de la operación en campo) | F38: 46113 | G38: Cuenta de cobro 0126 | H38: 8000000 | I38: PAGADA | J38: 46126 | K38: CP
C39: Jose del Carmen Rojas | D39: Insumos ferreteria | E39: Insumos Ferreteria | F39: 46098 | G39: N 52720 | H39: 4406500 | I39: PAGADA | J39: 46126 | K39: CP
C40: Jose James Correa | D40: Alquiler vehiculo pozo KIMBO - ODT mes febrero 2026 | E40: Arrendamientos Operativos | F40: 46090 | G40: Cuenta de Cobro 0052026 | H40: 4000000 | I40: PAGADA | J40: 46126 | K40: CP
C41: Jose del Carmen Rojas | D41: Insumos campo | E41: Insumos Ferreteria | F41: 46097 | G41: N 52675 | H41: 3087000 | I41: PAGADA | J41: 46126 | K41: CP
C42: CAPROIN S.A | D42: Insumos campo | E42: Repuestos Generales | F42: 46126 | G42: Orden de compra 260417 | H42: 2438072 | I42: PAGADA | J42: 46126 | K42: CP
C43: EMMANUEL DOTACIONES | D43: Dotacion | E43: Nominas y prestaciones (Nominas, examenes medicos, dotacion, seguridad social) | F43: 46098 | G43: CT1 8189 | H43: 2159100 | I43: PAGADA | J43: 46126 | K43: CP
C44: TRANSLOGIC COLOMBIA SAS | D44: Transporte personal | E44: Servicios Integrales (Multiples servicios para el desarrollo de la operación en campo) | F44: 46090 | G44: FE 131 | H44: 2000000 | I44: PAGADA | J44: 46126 | K44: CP
C45: EMMANUEL DOTACIONES | D45: Dotacion | E45: Nominas y prestaciones (Nominas, examenes medicos, dotacion, seguridad social) | F45: 46120 | G45: CT1 8370 | H45: 1933600 | I45: PAGADA | J45: 46126 | K45: CP
C46: Nhora Rocio Pacativa | D46: Dotacion | E46: Nominas y prestaciones (Nominas, examenes medicos, dotacion, seguridad social) | F46: 46118 | G46: Cuenta de cobro 004 | H46: 1832000 | I46: PAGADA | J46: 46126 | K46: CP
...
